Traceback (most recent call last):
  File "Password_generator.py", line 404, in <module>
  File "Password_generator.py", line 29, in connect
sqlite3.OperationalError: unable to open database file
Traceback (most recent call last):
  File "Password_generator.py", line 404, in <module>
  File "Password_generator.py", line 29, in connect
sqlite3.OperationalError: unable to open database file
Traceback (most recent call last):
  File "Password_generator.py", line 11, in <module>
NameError: name '__file__' is not defined
Traceback (most recent call last):
  File "Password_generator.py", line 11, in <module>
NameError: name '__file__' is not defined
Traceback (most recent call last):
  File "Password_generator.py", line 11, in <module>
NameError: name '__file__' is not defined
